Workbook

Sheet EGR2023_MASTER
D1: EGR 2022 ANALYSIS (Fig 3_4), extended with other sources (all incl. LULUCF) | O1: CLIMATE WATCH ANALYSIS | P1: CAT | Q1: EGR2022 | W1: EGR2023 | Z1: CAT | AA1: EGR2022 | AH1: OLD-NOT USED | AI1: OLD-NOT USED
A2: Country | B2: 3LC | D2: Current emissions | H2: NDC Emissions | I2: Current Policies | J2: CAIT Data | L2: Net zero target | Q2: Current policy projection on downward path (2030 emissions, incl. LULUCF, at least 10% below 2020) | R2: Added 23 Feb | S2: Added 23 Feb | T2: Confidence assessment | W2: UNEP EGR2023 implementation progress assessment
C3: Unit | D3: Year | E3: Total | F3: 2020 | G3: Year | H3: Total | I3: Total | J3: Emissions (MtCO2e/yr, 2019) | K3: Share of global emissions | L3: Year | M3: Total | N3: Net zero target applicable to | O3: Legally binding | P3: Published plan (BOLD: manually coded) | Q3: 10% below 2020 | R3: 0% below 2020 | S3: 20% below 2020 | T3: 0.1 | U3: 0 | V3: 0.2 | W3: 0.1 | X3: 0 | Y3: 0.2 | Z3: Published plan assessment notes | AA3: Current policy trends (and 2020 emission estimates where relevant) - assessment notes for 10% threshold | AB3: Source Current Policy projection trends | AH3: NDC on downward path (2030 emissions at least 10% below last historic data point) | AI3: Current policy projection on downward path (2030 emissions at least 10% below last historic data point)
A4: Argentina | B4: ARG | C4: MtCO2e/yr | D4: 2016 | E4: 378 | F4: 367.67525 | G4: 2030 | H4: 375 | I4: 424 | J4: 398.91 | K4: =J4/49758.23 -> 0.0080169652 | L4: 2050 | M4: 0 | N4: GHG | O4: N | P4: {=INDEX(CAT_NZ_Nov22!$Q$16:$Q$54,MATCH($B4,CAT_NZ_Nov22!$C$16:$C$53,0))} -> Weaker | Q4: n | R4: n | S4: n | T4: =IF(AND(O4="Y",AND(P4="credible",Q4="Y")),"higher",IF(Q4="Y","lower",IF(AND(Q4="N",OR(O4="Y",P4="credible")),"lower","much lower"))) -> much lower | U4: =IF(AND(O4="Y",AND(P4="credible",R4="Y")),"higher",IF(R4="Y","lower",IF(AND(R4="N",OR(O4="Y",P4="credible")),"lower","much lower"))) -> much lower | V4: =IF(AND(O4="Y",AND(P4="credible",S4="Y")),"higher",IF(S4="Y","lower",IF(AND(S4="N",OR(O4="Y",P4="credible")),"lower","much lower"))) -> much lower | W4: =IF(AND($P4="credible",Q4="Y"),"stronger","weak") -> weak | X4: =IF(AND($P4="credible",R4="Y"),"stronger","weak") -> weak | Y4: =IF(AND($P4="credible",S4="Y"),"stronger","weak") -> weak | Z4: See 'CAT_NZ_Nov22' sheet | AB4: Figure 3.4 UNEP Emissions Gap report Chapter 3 | AF4: n | AH4: N | AI4: =IF(I4<0.9*J4,"Y","N") -> N
A5: Australia | B5: AUS | C5: MtCO2e/yr | D5: 2020 | E5: 503 | F5: 568.40599 | G5: 2030 | H5: 347 | I5: 458 | J5: 608.49 | K5: =J5/49758.23 -> 0.012228932 | L5: 2050 | M5: 0 | N5: GHG | O5: Y | P5: {=INDEX(CAT_NZ_Nov22!$Q$16:$Q$54,MATCH($B5,CAT_NZ_Nov22!$C$16:$C$53,0))} -> Weaker | Q5: n | R5: y | S5: n | T5: =IF(AND(O5="Y",AND(P5="credible",Q5="Y")),"higher",IF(Q5="Y","lower",IF(AND(Q5="N",OR(O5="Y",P5="credible")),"lower","much lower"))) -> lower | U5: =IF(AND(O5="Y",AND(P5="credible",R5="Y")),"higher",IF(R5="Y","lower",IF(AND(R5="N",OR(O5="Y",P5="credible")),"lower","much lower"))) -> lower | V5: =IF(AND(O5="Y",AND(P5="credible",S5="Y")),"higher",IF(S5="Y","lower",IF(AND(S5="N",OR(O5="Y",P5="credible")),"lower","much lower"))) -> lower | W5: =IF(AND($P5="credible",Q5="Y"),"stronger","weak") -> weak | X5: =IF(AND($P5="credible",R5="Y"),"stronger","weak") -> weak | Y5: =IF(AND($P5="credible",S5="Y"),"stronger","weak") -> weak | Z5: See 'CAT_NZ_Nov22' sheet | AA5: 3 of 5 says no. Nascimento et al 2022 reports between -34% to -16% below 2015 levels. JRC reports an increase | AB5: Figure 3.4 UNEP Emissions Gap report Chapter 3 | AF5: n | AH5: Y | AI5: =IF(I5<0.9*J5,"Y","N") -> Y
A6: Bahrain | B6: BHR | C6: MtCO2e/yr | F6: 66.304879 | L6: 2060 | M6: 0 | N6: GHG | O6: N | W6: weak
A7: Brazil | B7: BRA | C7: MtCO2e/yr | D7: 2018 | E7: 1366 | F7: 2228.2034 | G7: 2030 | H7: 1268 | I7: 1541 | J7: 1451.63 | K7: =J7/49758.23 -> 0.029173666 | L7: 2050 | M7: 0 | N7: UNCLEAR | O7: N | P7: {=INDEX(CAT_NZ_Nov22!$Q$16:$Q$54,MATCH($B7,CAT_NZ_Nov22!$C$16:$C$53,0))} -> None | Q7: n | R7: n | S7: n | T7: =IF(AND(O7="Y",AND(P7="credible",Q7="Y")),"higher",IF(Q7="Y","lower",IF(AND(Q7="N",OR(O7="Y",P7="credible")),"lower","much lower"))) -> much lower | U7: =IF(AND(O7="Y",AND(P7="credible",R7="Y")),"higher",IF(R7="Y","lower",IF(AND(R7="N",OR(O7="Y",P7="credible")),"lower","much lower"))) -> much lower | V7: =IF(AND(O7="Y",AND(P7="credible",S7="Y")),"higher",IF(S7="Y","lower",IF(AND(S7="N",OR(O7="Y",P7="credible")),"lower","much lower"))) -> much lower | W7: =IF(AND($P7="credible",Q7="Y"),"stronger","weak") -> weak | X7: =IF(AND($P7="credible",R7="Y"),"stronger","weak") -> weak | Y7: =IF(AND($P7="credible",S7="Y"),"stronger","weak") -> weak | Z7: See 'CAT_NZ_Nov22' sheet | AB7: Figure 3.4 UNEP Emissions Gap report Chapter 3 | AF7: n | AH7: N | AI7: =IF(I7<0.9*J7,"Y","N") -> N
A8: Canada | B8: CAN | C8: MtCO2e/yr | D8: 2020 | E8: 638 | F8: 757.16091 | G8: 2030 | H8: 427 | I8: 621 | J8: 774.29 | K8: =J8/49758.23 -> 0.015561044 | L8: 2050 | M8: 0 | N8: GHG | O8: Y | P8: {=INDEX(CAT_NZ_Nov22!$Q$16:$Q$54,MATCH($B8,CAT_NZ_Nov22!$C$16:$C$53,0))} -> Credible | Q8: n | R8: n | S8: n | T8: =IF(AND(O8="Y",AND(P8="credible",Q8="Y")),"higher",IF(Q8="Y","lower",IF(AND(Q8="N",OR(O8="Y",P8="credible")),"lower","much lower"))) -> lower | U8: =IF(AND(O8="Y",AND(P8="credible",R8="Y")),"higher",IF(R8="Y","lower",IF(AND(R8="N",OR(O8="Y",P8="credible")),"lower","much lower"))) -> lower | V8: =IF(AND(O8="Y",AND(P8="credible",S8="Y")),"higher",IF(S8="Y","lower",IF(AND(S8="N",OR(O8="Y",P8="credible")),"lower","much lower"))) -> lower | W8: =IF(AND($P8="credible",Q8="Y"),"stronger","weak") -> weak | X8: =IF(AND($P8="credible",R8="Y"),"stronger","weak") -> weak | Y8: =IF(AND($P8="credible",S8="Y"),"stronger","weak") -> weak | Z8: See 'CAT_NZ_Nov22' sheet | AA8: 3 of 4 says no, incl. official projection. Only JRC projects -21% reduction. Official projections also only -3%. Nascimento et al 2022 reports between -3% and 0% below 2015 levels. | AB8: Figure 3.4 UNEP Emissions Gap report Chapter 3 | AF8: n | AH8: Y | AI8: =IF(I8<0.9*J8,"Y","N") -> Y
A9: Switzerland | B9: CHE | C9: MtCO2e/yr | F9: 41.187815 | L9: 2050 | M9: 0 | N9: GHG | O9: Y | P9: {=INDEX(CAT_NZ_Nov22!$Q$16:$Q$54,MATCH($B9,CAT_NZ_Nov22!$C$16:$C$53,0))} -> Credible | W9: stronger
A10: China | B10: CHN | C10: MtCO2e/yr | D10: 2018 | E10: 12233 | F10: 13283.73 | G10: 2030 | H10: 14092 | I10: 14705 | J10: 12055.41 | K10: =J10/49758.23 -> 0.24227972 | L10: 2060 | M10: 0 | N10: UNCLEAR | O10: N | P10: {=INDEX(CAT_NZ_Nov22!$Q$16:$Q$54,MATCH($B10,CAT_NZ_Nov22!$C$16:$C$53,0))} -> Credible | Q10: n | R10: n | S10: n | T10: =IF(AND(O10="Y",AND(P10="credible",Q10="Y")),"higher",IF(Q10="Y","lower",IF(AND(Q10="N",OR(O10="Y",P10="credible")),"lower","much lower"))) -> lower | U10: =IF(AND(O10="Y",AND(P10="credible",R10="Y")),"higher",IF(R10="Y","lower",IF(AND(R10="N",OR(O10="Y",P10="credible")),"lower","much lower"))) -> lower | V10: =IF(AND(O10="Y",AND(P10="credible",S10="Y")),"higher",IF(S10="Y","lower",IF(AND(S10="N",OR(O10="Y",P10="credible")),"lower","much lower"))) -> lower | W10: =IF(AND($P10="credible",Q10="Y"),"stronger","weak") -> weak | X10: =IF(AND($P10="credible",R10="Y"),"stronger","weak") -> weak | Y10: =IF(AND($P10="credible",S10="Y"),"stronger","weak") -> weak | Z10: See 'CAT_NZ_Nov22' sheet | AB10: Figure 3.4 UNEP Emissions Gap report Chapter 3 | AF10: n | AH10: N | AI10: =IF(I10<0.9*J10,"Y","N") -> N
A11: European Union | B11: EU27 | C11: MtCO2e/yr | D11: 2020 | E11: 3043 | F11: 3046 | G11: 2030 | H11: 2146 | I11: 2426 | J11: 3149.57 | K11: =J11/49758.23 -> 0.063297469 | L11: 2050 | M11: 0 | N11: GHG | O11: Y | P11: {=INDEX(CAT_NZ_Nov22!$Q$16:$Q$54,MATCH($B11,CAT_NZ_Nov22!$C$16:$C$53,0))} -> Credible | Q11: y | R11: y | S11: n | T11: =IF(AND(O11="Y",AND(P11="credible",Q11="Y")),"higher",IF(Q11="Y","lower",IF(AND(Q11="N",OR(O11="Y",P11="credible")),"lower","much lower"))) -> higher | U11: =IF(AND(O11="Y",AND(P11="credible",R11="Y")),"higher",IF(R11="Y","lower",IF(AND(R11="N",OR(O11="Y",P11="credible")),"lower","much lower"))) -> higher | V11: =IF(AND(O11="Y",AND(P11="credible",S11="Y")),"higher",IF(S11="Y","lower",IF(AND(S11="N",OR(O11="Y",P11="credible")),"lower","much lower"))) -> lower | W11: =IF(AND($P11="credible",Q11="Y"),"stronger","weak") -> stronger | X11: =IF(AND($P11="credible",R11="Y"),"stronger","weak") -> stronger | Y11: =IF(AND($P11="credible",S11="Y"),"stronger","weak") -> weak | Z11: See 'CAT_NZ_Nov22' sheet | AB11: Figure 3.4 UNEP Emissions Gap report Chapter 3 | AF11: y | AH11: Y | AI11: =IF(I11<0.9*J11,"Y","N") -> Y
A12: Ghana | B12: GHA | C12: MtCO2e/yr | F12: 52.120976 | L12: 2070 | N12: CO2 | O12: N | P12: {=INDEX(CAT_NZ_Nov22!$Q$16:$Q$54,MATCH($B12,CAT_NZ_Nov22!$C$16:$C$53,0))} -> #N/A | W12: weak
A13: India | B13: IND | C13: MtCO2e/yr | D13: 2018 | E13: 2692 | F13: 3626.7377 | G13: 2030 | H13: 4934 | I13: 4893 | J13: 3363.59 | K13: =J13/49758.23 -> 0.067598667 | L13: 2070 | M13: 0 | N13: UNCLEAR | O13: N | P13: {=INDEX(CAT_NZ_Nov22!$Q$16:$Q$54,MATCH($B13,CAT_NZ_Nov22!$C$16:$C$53,0))} -> None | Q13: n | R13: n | S13: n | T13: =IF(AND(O13="Y",AND(P13="credible",Q13="Y")),"higher",IF(Q13="Y","lower",IF(AND(Q13="N",OR(O13="Y",P13="credible")),"lower","much lower"))) -> much lower | U13: =IF(AND(O13="Y",AND(P13="credible",R13="Y")),"higher",IF(R13="Y","lower",IF(AND(R13="N",OR(O13="Y",P13="credible")),"lower","much lower"))) -> much lower | V13: =IF(AND(O13="Y",AND(P13="credible",S13="Y")),"higher",IF(S13="Y","lower",IF(AND(S13="N",OR(O13="Y",P13="credible")),"lower","much lower"))) -> much lower | W13: =IF(AND($P13="credible",Q13="Y"),"stronger","weak") -> weak | X13: =IF(AND($P13="credible",R13="Y"),"stronger","weak") -> weak | Y13: =IF(AND($P13="credible",S13="Y"),"stronger","weak") -> weak | Z13: See 'CAT_NZ_Nov22' sheet | AB13: Figure 3.4 UNEP Emissions Gap report Chapter 3 | AF13: n | AH13: N | AI13: =IF(I13<0.9*J13,"Y","N") -> N
A14: Indonesia | B14: IDN | C14: MtCO2e/yr | D14: 2016 | E14: 1491 | F14: 1931.1034 | G14: 2030 | H14: 2130 | I14: 1877 | J14: 1959.71 | K14: =J14/49758.23 -> 0.03938464 | L14: 2060 | M14: 0 | N14: UNCLEAR | O14: N | P14: {=INDEX(CAT_NZ_Nov22!$Q$16:$Q$54,MATCH($B14,CAT_NZ_Nov22!$C$16:$C$53,0))} -> None | Q14: n | R14: n | S14: n | T14: =IF(AND(O14="Y",AND(P14="credible",Q14="Y")),"higher",IF(Q14="Y","lower",IF(AND(Q14="N",OR(O14="Y",P14="credible")),"lower","much lower"))) -> much lower | U14: =IF(AND(O14="Y",AND(P14="credible",R14="Y")),"higher",IF(R14="Y","lower",IF(AND(R14="N",OR(O14="Y",P14="credible")),"lower","much lower"))) -> much lower | V14: =IF(AND(O14="Y",AND(P14="credible",S14="Y")),"higher",IF(S14="Y","lower",IF(AND(S14="N",OR(O14="Y",P14="credible")),"lower","much lower"))) -> much lower | W14: =IF(AND($P14="credible",Q14="Y"),"stronger","weak") -> weak | X14: =IF(AND($P14="credible",R14="Y"),"stronger","weak") -> weak | Y14: =IF(AND($P14="credible",S14="Y"),"stronger","weak") -> weak | Z14: See 'CAT_NZ_Nov22' sheet | AB14: Figure 3.4 UNEP Emissions Gap report Chapter 3 | AF14: n | AH14: N | AI14: =IF(I14<0.9*J14,"Y","N") -> N
A15: Japan | B15: JPN | C15: MtCO2e/yr | D15: 2020 | E15: 1070 | F15: 1078.7547 | G15: 2030 | H15: 767 | I15: 982 | J15: 1134.45 | K15: =J15/49758.23 -> 0.022799243 | L15: 2050 | M15: 0 | N15: GHG | O15: Y | P15: {=INDEX(CAT_NZ_Nov22!$Q$16:$Q$54,MATCH($B15,CAT_NZ_Nov22!$C$16:$C$53,0))} -> Credible | Q15: n | R15: y | S15: n | T15: =IF(AND(O15="Y",AND(P15="credible",Q15="Y")),"higher",IF(Q15="Y","lower",IF(AND(Q15="N",OR(O15="Y",P15="credible")),"lower","much lower"))) -> lower | U15: =IF(AND(O15="Y",AND(P15="credible",R15="Y")),"higher",IF(R15="Y","lower",IF(AND(R15="N",OR(O15="Y",P15="credible")),"lower","much lower"))) -> higher | V15: =IF(AND(O15="Y",AND(P15="credible",S15="Y")),"higher",IF(S15="Y","lower",IF(AND(S15="N",OR(O15="Y",P15="credible")),"lower","much lower"))) -> lower | W15: =IF(AND($P15="credible",Q15="Y"),"stronger","weak") -> weak | X15: =IF(AND($P15="credible",R15="Y"),"stronger","weak") -> stronger | Y15: =IF(AND($P15="credible",S15="Y"),"stronger","weak") -> weak | Z15: See 'CAT_NZ_Nov22' sheet | AA15: 2 of 3 says no. Only CAT lower bound projects -20% reduction. Nascimento et al 2022 reports between -31% and -18% below 2015 levels. JRC shows similar result | AB15: Figure 3.4 UNEP Emissions Gap report Chapter 3 | AF15: n | AH15: Y | AI15: =IF(I15<0.9*J15,"Y","N") -> Y
A16: Mexico | B16: MEX | C16: MtCO2e/yr | D16: 2017 | E16: 577 | F16: 864.23828 | G16: 2030 | H16: 772 | I16: 725 | J16: 670.84 | K16: =J16/49758.23 -> 0.013481991 | L16: 2050 | M16: =558.02/2 -> 279.01 | N16: NOTARGET | O16: No NZT | P16: {=INDEX(CAT_NZ_Nov22!$Q$16:$Q$54,MATCH($B16,CAT_NZ_Nov22!$C$16:$C$53,0))} -> None | Q16: n | R16: n | S16: n | T16: =IF(AND(O16="Y",AND(P16="credible",Q16="Y")),"higher",IF(Q16="Y","lower",IF(AND(Q16="N",OR(O16="Y",P16="credible")),"lower","much lower"))) -> much lower | U16: =IF(AND(O16="Y",AND(P16="credible",R16="Y")),"higher",IF(R16="Y","lower",IF(AND(R16="N",OR(O16="Y",P16="credible")),"lower","much lower"))) -> much lower | V16: =IF(AND(O16="Y",AND(P16="credible",S16="Y")),"higher",IF(S16="Y","lower",IF(AND(S16="N",OR(O16="Y",P16="credible")),"lower","much lower"))) -> much lower | W16: =IF(AND($P16="credible",Q16="Y"),"stronger","weak") -> weak | X16: =IF(AND($P16="credible",R16="Y"),"stronger","weak") -> weak | Y16: =IF(AND($P16="credible",S16="Y"),"stronger","weak") -> weak | Z16: See 'CAT_NZ_Nov22' sheet | AB16: Figure 3.4 UNEP Emissions Gap report Chapter 3 | AF16: n | AH16: N | AI16: =IF(I16<0.9*J16,"Y","N") -> N
A17: Republic of Korea | B17: KOR | C17: MtCO2e/yr | D17: 2017 | E17: 672 | F17: 641.52027 | G17: 2030 | H17: 437 | I17: 593 | J17: 652.66 | K17: =J17/49758.23 -> 0.013116624 | L17: 2050 | M17: 0 | N17: GHG | O17: Y | P17: {=INDEX(CAT_NZ_Nov22!$Q$16:$Q$54,MATCH($B17,CAT_NZ_Nov22!$C$16:$C$53,0))} -> Credible | Q17: n | R17: y | S17: n | T17: =IF(AND(O17="Y",AND(P17="credible",Q17="Y")),"higher",IF(Q17="Y","lower",IF(AND(Q17="N",OR(O17="Y",P17="credible")),"lower","much lower"))) -> lower | U17: =IF(AND(O17="Y",AND(P17="credible",R17="Y")),"higher",IF(R17="Y","lower",IF(AND(R17="N",OR(O17="Y",P17="credible")),"lower","much lower"))) -> higher | V17: =IF(AND(O17="Y",AND(P17="credible",S17="Y")),"higher",IF(S17="Y","lower",IF(AND(S17="N",OR(O17="Y",P17="credible")),"lower","much lower"))) -> lower | W17: =IF(AND($P17="credible",Q17="Y"),"stronger","weak") -> weak | X17: =IF(AND($P17="credible",R17="Y"),"stronger","weak") -> stronger | Y17: =IF(AND($P17="credible",S17="Y"),"stronger","weak") -> weak | Z17: See 'CAT_NZ_Nov22' sheet | AA17: 2 of 3 says yes (CAT say no). | AB17: Figure 3.4 UNEP Emissions Gap report Chapter 3 | AF17: y | AH17: Y | AI17: =IF(I17<0.9*J17,"Y","N") -> N
A18: Kuwait | B18: KWT | C18: MtCO2e/yr | F18: 137.02112 | L18: 2060 | M18: 0 | N18: CO2 | O18: N | P18: {=INDEX(CAT_NZ_Nov22!$Q$16:$Q$54,MATCH($B18,CAT_NZ_Nov22!$C$16:$C$53,0))} -> #N/A | W18: weak
A19: Laos | B19: LAO | C19: MtCO2e/yr | F19: 67.476743 | L19: 2050 | M19: 0 | N19: GHG | O19: N | P19: {=INDEX(CAT_NZ_Nov22!$Q$16:$Q$54,MATCH($B19,CAT_NZ_Nov22!$C$16:$C$53,0))} -> #N/A | W19: weak
A20: Russian Federation | B20: RUS | C20: MtCO2e/yr | D20: 2018 | E20: 1629 | F20: 2235.4309 | G20: 2030 | H20: 2205 | I20: 1794 | J20: 1924.82 | K20: =J20/49758.23 -> 0.03868345 | L20: 2060 | M20: 0 | N20: UNCLEAR | O20: Y | P20: {=INDEX(CAT_NZ_Nov22!$Q$16:$Q$54,MATCH($B20,CAT_NZ_Nov22!$C$16:$C$53,0))} -> Credible | Q20: n | R20: n | S20: n | T20: =IF(AND(O20="Y",AND(P20="credible",Q20="Y")),"higher",IF(Q20="Y","lower",IF(AND(Q20="N",OR(O20="Y",P20="credible")),"lower","much lower"))) -> lower | U20: =IF(AND(O20="Y",AND(P20="credible",R20="Y")),"higher",IF(R20="Y","lower",IF(AND(R20="N",OR(O20="Y",P20="credible")),"lower","much lower"))) -> lower | V20: =IF(AND(O20="Y",AND(P20="credible",S20="Y")),"higher",IF(S20="Y","lower",IF(AND(S20="N",OR(O20="Y",P20="credible")),"lower","much lower"))) -> lower | W20: =IF(AND($P20="credible",Q20="Y"),"stronger","weak") -> weak | X20: =IF(AND($P20="credible",R20="Y"),"stronger","weak") -> weak | Y20: =IF(AND($P20="credible",S20="Y"),"stronger","weak") -> weak | Z20: See 'CAT_NZ_Nov22' sheet | AB20: Figure 3.4 UNEP Emissions Gap report Chapter 3 | AF20: n | AH20: N | AI20: =IF(I20<0.9*J20,"Y","N") -> N
A21: Saudi Arabia | B21: SAU | C21: MtCO2e/yr | D21: 2015 | E21: 640 | F21: 749.85291 | G21: 2030 | H21: 650 | I21: 690 | J21: 723.15 | K21: =J21/49758.23 -> 0.014533274 | L21: 2060 | M21: 0 | N21: UNCLEAR | O21: N | P21: {=INDEX(CAT_NZ_Nov22!$Q$16:$Q$54,MATCH($B21,CAT_NZ_Nov22!$C$16:$C$53,0))} -> Weaker | Q21: n | R21: n | S21: n | T21: =IF(AND(O21="Y",AND(P21="credible",Q21="Y")),"higher",IF(Q21="Y","lower",IF(AND(Q21="N",OR(O21="Y",P21="credible")),"lower","much lower"))) -> much lower | U21: =IF(AND(O21="Y",AND(P21="credible",R21="Y")),"higher",IF(R21="Y","lower",IF(AND(R21="N",OR(O21="Y",P21="credible")),"lower","much lower"))) -> much lower | V21: =IF(AND(O21="Y",AND(P21="credible",S21="Y")),"higher",IF(S21="Y","lower",IF(AND(S21="N",OR(O21="Y",P21="credible")),"lower","much lower"))) -> much lower | W21: =IF(AND($P21="credible",Q21="Y"),"stronger","weak") -> weak | X21: =IF(AND($P21="credible",R21="Y"),"stronger","weak") -> weak | Y21: =IF(AND($P21="credible",S21="Y"),"stronger","weak") -> weak | Z21: See 'CAT_NZ_Nov22' sheet | AB21: Figure 3.4 UNEP Emissions Gap report Chapter 3 | AF21: n | AH21: N | AI21: =IF(I21<0.9*J21,"Y","N") -> N
A22: South Africa | B22: ZAF | C22: MtCO2e/yr | D22: 2017 | E22: 528 | F22: 549.74934 | G22: 2030 | H22: 399 | I22: 444 | J22: 562.19 | K22: =J22/49758.23 -> 0.011298432 | L22: 2050 | M22: 0 | N22: CO2 | O22: N | P22: {=INDEX(CAT_NZ_Nov22!$Q$16:$Q$54,MATCH($B22,CAT_NZ_Nov22!$C$16:$C$53,0))} -> None | Q22: n | R22: y | S22: n | T22: =IF(AND(O22="Y",AND(P22="credible",Q22="Y")),"higher",IF(Q22="Y","lower",IF(AND(Q22="N",OR(O22="Y",P22="credible")),"lower","much lower"))) -> much lower | U22: =IF(AND(O22="Y",AND(P22="credible",R22="Y")),"higher",IF(R22="Y","lower",IF(AND(R22="N",OR(O22="Y",P22="credible")),"lower","much lower"))) -> lower | V22: =IF(AND(O22="Y",AND(P22="credible",S22="Y")),"higher",IF(S22="Y","lower",IF(AND(S22="N",OR(O22="Y",P22="credible")),"lower","much lower"))) -> much lower | W22: =IF(AND($P22="credible",Q22="Y"),"stronger","weak") -> weak | X22: =IF(AND($P22="credible",R22="Y"),"stronger","weak") -> weak | Y22: =IF(AND($P22="credible",S22="Y"),"stronger","weak") -> weak | Z22: See 'CAT_NZ_Nov22' sheet | AA22: 2 of 3 says yes (CAT say no). CAT not on track, JRC and PBL shows more than -10% reduction. Nascimento et al 2022 reports between -19% and -5% below 2015 levels. JRC also has a decrease of more than 20% | AB22: Figure 3.4 UNEP Emissions Gap report Chapter 3 | AF22: y | AH22: Y | AI22: =IF(I22<0.9*J22,"Y","N") -> Y
A23: Turkiye | B23: TUR | C23: MtCO2e/yr | D23: 2018 | E23: 426 | F23: 547.64201 | G23: 2030 | H23: 936 | I23: 569 | J23: 459.86 | K23: =J23/49758.23 -> 0.0092418882 | L23: 2053 | M23: 0 | N23: UNCLEAR | O23: N | P23: {=INDEX(CAT_NZ_Nov22!$Q$16:$Q$54,MATCH($B23,CAT_NZ_Nov22!$C$16:$C$53,0))} -> Credible | Q23: n | R23: n | S23: n | T23: =IF(AND(O23="Y",AND(P23="credible",Q23="Y")),"higher",IF(Q23="Y","lower",IF(AND(Q23="N",OR(O23="Y",P23="credible")),"lower","much lower"))) -> lower | U23: =IF(AND(O23="Y",AND(P23="credible",R23="Y")),"higher",IF(R23="Y","lower",IF(AND(R23="N",OR(O23="Y",P23="credible")),"lower","much lower"))) -> lower | V23: =IF(AND(O23="Y",AND(P23="credible",S23="Y")),"higher",IF(S23="Y","lower",IF(AND(S23="N",OR(O23="Y",P23="credible")),"lower","much lower"))) -> lower | W23: =IF(AND($P23="credible",Q23="Y"),"stronger","weak") -> weak | X23: =IF(AND($P23="credible",R23="Y"),"stronger","weak") -> weak | Y23: =IF(AND($P23="credible",S23="Y"),"stronger","weak") -> weak | Z23: See 'CAT_NZ_Nov22' sheet | AB23: Figure 3.4 UNEP Emissions Gap report Chapter 3 | AF23: n | AH23: N | AI23: =IF(I23<0.9*J23,"Y","N") -> N
A24: United Kingdom of Great Britain and Northern Ireland | B24: GBR | C24: MtCO2e/yr | D24: 2020 | E24: 396 | F24: 416.13753 | G24: 2030 | H24: 277 | I24: 356 | J24: 429.13 | K24: =J24/49758.23 -> 0.0086243019 | L24: 2050 | M24: 0 | N24: GHG | O24: Y | P24: {=INDEX(CAT_NZ_Nov22!$Q$16:$Q$54,MATCH($B24,CAT_NZ_Nov22!$C$16:$C$53,0))} -> Credible | Q24: y | R24: y | S24: n | T24: =IF(AND(O24="Y",AND(P24="credible",Q24="Y")),"higher",IF(Q24="Y","lower",IF(AND(Q24="N",OR(O24="Y",P24="credible")),"lower","much lower"))) -> higher | U24: =IF(AND(O24="Y",AND(P24="credible",R24="Y")),"higher",IF(R24="Y","lower",IF(AND(R24="N",OR(O24="Y",P24="credible")),"lower","much lower"))) -> higher | V24: =IF(AND(O24="Y",AND(P24="credible",S24="Y")),"higher",IF(S24="Y","lower",IF(AND(S24="N",OR(O24="Y",P24="credible")),"lower","much lower"))) -> lower | W24: =IF(AND($P24="credible",Q24="Y"),"stronger","weak") -> stronger | X24: =IF(AND($P24="credible",R24="Y"),"stronger","weak") -> stronger | Y24: =IF(AND($P24="credible",S24="Y"),"stronger","weak") -> weak | Z24: See 'CAT_NZ_Nov22' sheet | AB24: Figure 3.4 UNEP Emissions Gap report Chapter 3 | AF24: y | AH24: Y | AI24: =IF(I24<0.9*J24,"Y","N") -> Y
A25: United States of America | B25: USA | C25: MtCO2e/yr | D25: 2020 | E25: 5167 | F25: 5635.0954 | G25: 2030 | H25: 3279 | I25: 4164 | J25: 5771 | K25: =J25/49758.23 -> 0.11598081 | L25: 2050 | M25: 0 | N25: GHG | O25: N | P25: {=INDEX(CAT_NZ_Nov22!$Q$16:$Q$54,MATCH($B25,CAT_NZ_Nov22!$C$16:$C$53,0))} -> Credible | Q25: y | R25: y | S25: n | T25: =IF(AND(O25="Y",AND(P25="credible",Q25="Y")),"higher",IF(Q25="Y","lower",IF(AND(Q25="N",OR(O25="Y",P25="credible")),"lower","much lower"))) -> lower | U25: =IF(AND(O25="Y",AND(P25="credible",R25="Y")),"higher",IF(R25="Y","lower",IF(AND(R25="N",OR(O25="Y",P25="credible")),"lower","much lower"))) -> lower | V25: =IF(AND(O25="Y",AND(P25="credible",S25="Y")),"higher",IF(S25="Y","lower",IF(AND(S25="N",OR(O25="Y",P25="credible")),"lower","much lower"))) -> lower | W25: =IF(AND($P25="credible",Q25="Y"),"stronger","weak") -> stronger | X25: =IF(AND($P25="credible",R25="Y"),"stronger","weak") -> stronger | Y25: =IF(AND($P25="credible",S25="Y"),"stronger","weak") -> weak | Z25: See 'CAT_NZ_Nov22' sheet | AB25: Figure 3.4 UNEP Emissions Gap report Chapter 3 | AF25: y | AH25: Y | AI25: =IF(I25<0.9*J25,"Y","N") -> Y
A26: Malaysia | B26: MYS | C26: MtCO2e/yr | D26: 2018 | E26: 403 | F26: 462.96851 | G26: 2030 | H26: 383.7 | I26: 393.7 | J26: 396.11 | K26: =J26/49758.23 -> 0.0079606931 | L26: 2050 | M26: 0 | N26: UNCLEAR | O26: N | P26: None | Q26: n | R26: n | S26: n | T26: =IF(AND(O26="Y",AND(P26="credible",Q26="Y")),"higher",IF(Q26="Y","lower",IF(AND(Q26="N",OR(O26="Y",P26="credible")),"lower","much lower"))) -> much lower | U26: =IF(AND(O26="Y",AND(P26="credible",R26="Y")),"higher",IF(R26="Y","lower",IF(AND(R26="N",OR(O26="Y",P26="credible")),"lower","much lower"))) -> much lower | V26: =IF(AND(O26="Y",AND(P26="credible",S26="Y")),"higher",IF(S26="Y","lower",IF(AND(S26="N",OR(O26="Y",P26="credible")),"lower","much lower"))) -> much lower | W26: =IF(AND($P26="credible",Q26="Y"),"stronger","weak") -> weak | X26: =IF(AND($P26="credible",R26="Y"),"stronger","weak") -> weak | Y26: =IF(AND($P26="credible",S26="Y"),"stronger","weak") -> weak | Z26: The latest planning document states the 2050 net zero target, but the planning only goes up to 2025 (https://rmke12.epu.gov.my/file/download/2021092722_twelfth_malaysia_plan.pdf?path=fileUpload/2021/09/2021092722_twelfth_malaysia_plan.pdf&name=Twelfth%20Plan%20Document.pdf) | AA26: Keramidas et al. (2021) | AB26: http://doi.org/10.2760/410610 | AH26: N | AI26: =IF(I26<0.9*J26,"Y","N") -> N
A27: Namibia | B27: NAM | C27: MtCO2e/yr | F27: 21.257215 | L27: 2050 | M27: 0 | N27: GHG | O27: N | W27: weak
A28: Nigeria | B28: NGA | C28: MtCO2e/yr | D28: 2018 | E28: 360 | F28: 433.7823 | G28: 2030 | H28: 334 | I28: 375 | J28: 354.33 | K28: =J28/49758.23 -> 0.007121033 | L28: 2070 | M28: 0 | N28: GHG | O28: Y | P28: {=INDEX(CAT_NZ_Nov22!$Q$16:$Q$54,MATCH($B28,CAT_NZ_Nov22!$C$16:$C$53,0))} -> Credible | Q28: n | R28: n | S28: n | T28: =IF(AND(O28="Y",AND(P28="credible",Q28="Y")),"higher",IF(Q28="Y","lower",IF(AND(Q28="N",OR(O28="Y",P28="credible")),"lower","much lower"))) -> lower | U28: =IF(AND(O28="Y",AND(P28="credible",R28="Y")),"higher",IF(R28="Y","lower",IF(AND(R28="N",OR(O28="Y",P28="credible")),"lower","much lower"))) -> lower | V28: =IF(AND(O28="Y",AND(P28="credible",S28="Y")),"higher",IF(S28="Y","lower",IF(AND(S28="N",OR(O28="Y",P28="credible")),"lower","much lower"))) -> lower | W28: =IF(AND($P28="credible",Q28="Y"),"stronger","weak") -> weak | X28: =IF(AND($P28="credible",R28="Y"),"stronger","weak") -> weak | Y28: =IF(AND($P28="credible",S28="Y"),"stronger","weak") -> weak | Z28: See 'CAT_NZ_Nov22' sheet | AB28: https://climateactiontracker.org/countries/nigeria/ | AH28: N | AI28: =IF(I28<0.9*J28,"Y","N") -> N
A29: Oman | B29: OMN | C29: MtCO2e/yr | F29: 105.53455 | L29: 2050 | M29: 0 | N29: CO2 | O29: N | W29: weak
A30: Peru | B30: PER | C30: MtCO2e/yr | F30: 124.5853 | L30: 2050 | M30: 0 | N30: CO2 | O30: N | W30: weak
A31: Thailand | B31: THA | C31: MtCO2e/yr | D31: 2018 | E31: 360 | F31: 424.60294 | G31: 2030 | H31: 444 | I31: 444 | J31: 437.18 | K31: =J31/49758.23 -> 0.0087860842 | L31: 2050 | M31: 0 | N31: CO2 | O31: N | P31: {=INDEX(CAT_NZ_Nov22!$Q$16:$Q$54,MATCH($B31,CAT_NZ_Nov22!$C$16:$C$53,0))} -> Credible | Q31: n | R31: n | S31: n | T31: =IF(AND(O31="Y",AND(P31="credible",Q31="Y")),"higher",IF(Q31="Y","lower",IF(AND(Q31="N",OR(O31="Y",P31="credible")),"lower","much lower"))) -> lower | U31: =IF(AND(O31="Y",AND(P31="credible",R31="Y")),"higher",IF(R31="Y","lower",IF(AND(R31="N",OR(O31="Y",P31="credible")),"lower","much lower"))) -> lower | V31: =IF(AND(O31="Y",AND(P31="credible",S31="Y")),"higher",IF(S31="Y","lower",IF(AND(S31="N",OR(O31="Y",P31="credible")),"lower","much lower"))) -> lower | W31: =IF(AND($P31="credible",Q31="Y"),"stronger","weak") -> weak | X31: =IF(AND($P31="credible",R31="Y"),"stronger","weak") -> weak | Y31: =IF(AND($P31="credible",S31="Y"),"stronger","weak") -> weak | Z31: See 'CAT_NZ_Nov22' sheet | AB31: https://newclimate.org/resources/publications/emissions-scenarios-for-major-economies-2022-update | AH31: N | AI31: =IF(I31<0.9*J31,"Y","N") -> N
A32: Kazakhstan | B32: KAZ | C32: MtCO2e/yr | D32: 2018 | E32: 351 | F32: 345.13657 | G32: 2030 | H32: 324.44 | I32: 443 | J32: 271.68 | K32: =J32/49758.23 -> 0.0054600013 | L32: 2060 | M32: 0 | N32: GHG | O32: N | P32: {=INDEX(CAT_NZ_Nov22!$Q$16:$Q$54,MATCH($B32,CAT_NZ_Nov22!$C$16:$C$53,0))} -> Credible | Q32: n | R32: n | S32: n | T32: =IF(AND(O32="Y",AND(P32="credible",Q32="Y")),"higher",IF(Q32="Y","lower",IF(AND(Q32="N",OR(O32="Y",P32="credible")),"lower","much lower"))) -> lower | U32: =IF(AND(O32="Y",AND(P32="credible",R32="Y")),"higher",IF(R32="Y","lower",IF(AND(R32="N",OR(O32="Y",P32="credible")),"lower","much lower"))) -> lower | V32: =IF(AND(O32="Y",AND(P32="credible",S32="Y")),"higher",IF(S32="Y","lower",IF(AND(S32="N",OR(O32="Y",P32="credible")),"lower","much lower"))) -> lower | W32: =IF(AND($P32="credible",Q32="Y"),"stronger","weak") -> weak | X32: =IF(AND($P32="credible",R32="Y"),"stronger","weak") -> weak | Y32: =IF(AND($P32="credible",S32="Y"),"stronger","weak") -> weak | Z32: See 'CAT_NZ_Nov22' sheet | AB32: https://newclimate.org/sites/default/files/2021/11/NewClimate_TrackingCurrentPolicies_Nov21.pdf | AH32: N | AI32: =IF(I32<0.9*J32,"Y","N") -> N
A33: Ukraine | B33: UKR | C33: MtCO2e/yr | D33: 2018 | E33: 341 | F33: 290.0207 | G33: 2030 | H33: 309 | I33: 426 | J33: 221.29 | K33: =J33/49758.23 -> 0.0044473045 | L33: 2060 | M33: 0 | N33: CO2 | O33: N | P33: None | Q33: n | R33: n | S33: n | T33: =IF(AND(O33="Y",AND(P33="credible",Q33="Y")),"higher",IF(Q33="Y","lower",IF(AND(Q33="N",OR(O33="Y",P33="credible")),"lower","much lower"))) -> much lower | U33: =IF(AND(O33="Y",AND(P33="credible",R33="Y")),"higher",IF(R33="Y","lower",IF(AND(R33="N",OR(O33="Y",P33="credible")),"lower","much lower"))) -> much lower | V33: =IF(AND(O33="Y",AND(P33="credible",S33="Y")),"higher",IF(S33="Y","lower",IF(AND(S33="N",OR(O33="Y",P33="credible")),"lower","much lower"))) -> much lower | W33: =IF(AND($P33="credible",Q33="Y"),"stronger","weak") -> weak | X33: =IF(AND($P33="credible",R33="Y"),"stronger","weak") -> weak | Y33: =IF(AND($P33="credible",S33="Y"),"stronger","weak") -> weak | Z33: CAT NZT evaluation Nov 2021 | AA33: Last CAT assessment in Nov 2021 | AB33: https://newclimate.org/sites/default/files/2021/11/NewClimate_TrackingCurrentPolicies_Nov21.pdf | AH33: N | AI33: =IF(I33<0.9*J33,"Y","N") -> N
A34: Vietnam | B34: VNM | C34: MtCO2e/yr | D34: 2018 | E34: 334 | F34: 633.68712 | G34: 2030 | H34: 844 | I34: 459 | J34: 438.11 | K34: =J34/49758.23 -> 0.0088047746 | L34: 2050 | M34: 0 | N34: UNCLEAR | O34: Y | P34: {=INDEX(CAT_NZ_Nov22!$Q$16:$Q$54,MATCH($B34,CAT_NZ_Nov22!$C$16:$C$53,0))} -> Credible | Q34: n | R34: n | S34: n | T34: =IF(AND(O34="Y",AND(P34="credible",Q34="Y")),"higher",IF(Q34="Y","lower",IF(AND(Q34="N",OR(O34="Y",P34="credible")),"lower","much lower"))) -> lower | U34: =IF(AND(O34="Y",AND(P34="credible",R34="Y")),"higher",IF(R34="Y","lower",IF(AND(R34="N",OR(O34="Y",P34="credible")),"lower","much lower"))) -> lower | V34: =IF(AND(O34="Y",AND(P34="credible",S34="Y")),"higher",IF(S34="Y","lower",IF(AND(S34="N",OR(O34="Y",P34="credible")),"lower","much lower"))) -> lower | W34: =IF(AND($P34="credible",Q34="Y"),"stronger","weak") -> weak | X34: =IF(AND($P34="credible",R34="Y"),"stronger","weak") -> weak | Y34: =IF(AND($P34="credible",S34="Y"),"stronger","weak") -> weak | Z34: See 'CAT_NZ_Nov22' sheet | AB34: https://newclimate.org/resources/publications/emissions-scenarios-for-major-economies-2022-update | AH34: N | AI34: =IF(I34<0.9*J34,"Y","N") -> N
A35: Colombia | B35: COL | C35: MtCO2e/yr | D35: 2018 | E35: 282 | F35: 255.60168 | G35: 2030 | H35: 164 | I35: 307 | J35: 270.53 | K35: =J35/49758.23 -> 0.0054368895 | L35: 2050 | M35: 0 | N35: GHG | O35: Y | P35: {=INDEX(CAT_NZ_Nov22!$Q$16:$Q$54,MATCH($B35,CAT_NZ_Nov22!$C$16:$C$53,0))} -> Credible | Q35: n | R35: n | S35: n | T35: =IF(AND(O35="Y",AND(P35="credible",Q35="Y")),"higher",IF(Q35="Y","lower",IF(AND(Q35="N",OR(O35="Y",P35="credible")),"lower","much lower"))) -> lower | U35: =IF(AND(O35="Y",AND(P35="credible",R35="Y")),"higher",IF(R35="Y","lower",IF(AND(R35="N",OR(O35="Y",P35="credible")),"lower","much lower"))) -> lower | V35: =IF(AND(O35="Y",AND(P35="credible",S35="Y")),"higher",IF(S35="Y","lower",IF(AND(S35="N",OR(O35="Y",P35="credible")),"lower","much lower"))) -> lower | W35: =IF(AND($P35="credible",Q35="Y"),"stronger","weak") -> weak | X35: =IF(AND($P35="credible",R35="Y"),"stronger","weak") -> weak | Y35: =IF(AND($P35="credible",S35="Y"),"stronger","weak") -> weak | Z35: See 'CAT_NZ_Nov22' sheet | AB35: https://newclimate.org/resources/publications/emissions-scenarios-for-major-economies-2022-update | AH35: Y | AI35: =IF(I35<0.9*J35,"Y","N") -> N
A36: United Arab Emirates | B36: ARE | C36: MtCO2e/yr | D36: 2018 | E36: 215 | F36: 269.39446 | G36: 2030 | H36: 208 | I36: 250 | J36: 243.55 | K36: =J36/49758.23 -> 0.0048946677 | L36: 2050 | M36: 0 | N36: GHG | O36: N | P36: {=INDEX(CAT_NZ_Nov22!$Q$16:$Q$54,MATCH($B36,CAT_NZ_Nov22!$C$16:$C$53,0))} -> None | Q36: n | R36: n | S36: n | T36: =IF(AND(O36="Y",AND(P36="credible",Q36="Y")),"higher",IF(Q36="Y","lower",IF(AND(Q36="N",OR(O36="Y",P36="credible")),"lower","much lower"))) -> much lower | U36: =IF(AND(O36="Y",AND(P36="credible",R36="Y")),"higher",IF(R36="Y","lower",IF(AND(R36="N",OR(O36="Y",P36="credible")),"lower","much lower"))) -> much lower | V36: =IF(AND(O36="Y",AND(P36="credible",S36="Y")),"higher",IF(S36="Y","lower",IF(AND(S36="N",OR(O36="Y",P36="credible")),"lower","much lower"))) -> much lower | W36: =IF(AND($P36="credible",Q36="Y"),"stronger","weak") -> weak | X36: =IF(AND($P36="credible",R36="Y"),"stronger","weak") -> weak | Y36: =IF(AND($P36="credible",S36="Y"),"stronger","weak") -> weak | Z36: See 'CAT_NZ_Nov22' sheet | AB36: https://newclimate.org/resources/publications/emissions-scenarios-for-major-economies-2022-update | AH36: N | AI36: =IF(I36<0.9*J36,"Y","N") -> N
A37: Chile | B37: CHL | C37: MtCO2e/yr | D37: 2018 | E37: 109 | F37: 119.11913 | G37: 2030 | H37: 81 | I37: 134 | J37: 55.33 | K37: =J37/49758.23 -> 0.0011119769 | L37: 2050 | M37: 0 | N37: GHG | O37: Y | P37: {=INDEX(CAT_NZ_Nov22!$Q$16:$Q$54,MATCH($B37,CAT_NZ_Nov22!$C$16:$C$53,0))} -> Credible | Q37: n | R37: n | S37: n | T37: =IF(AND(O37="Y",AND(P37="credible",Q37="Y")),"higher",IF(Q37="Y","lower",IF(AND(Q37="N",OR(O37="Y",P37="credible")),"lower","much lower"))) -> lower | U37: =IF(AND(O37="Y",AND(P37="credible",R37="Y")),"higher",IF(R37="Y","lower",IF(AND(R37="N",OR(O37="Y",P37="credible")),"lower","much lower"))) -> lower | V37: =IF(AND(O37="Y",AND(P37="credible",S37="Y")),"higher",IF(S37="Y","lower",IF(AND(S37="N",OR(O37="Y",P37="credible")),"lower","much lower"))) -> lower | W37: =IF(AND($P37="credible",Q37="Y"),"stronger","weak") -> weak | X37: =IF(AND($P37="credible",R37="Y"),"stronger","weak") -> weak | Y37: =IF(AND($P37="credible",S37="Y"),"stronger","weak") -> weak | Z37: See 'CAT_NZ_Nov22' sheet | AA37: Keramidas et al. (2021) | AB37: http://doi.org/10.2760/410610 | AH37: Y | AI37: =IF(I37<0.9*J37,"Y","N") -> N
A38: Egypt | B38: EGY | C38: MtCO2e/yr | D38: 2019 | E38: 353 | F38: 332 | G38: 2030 | H38: 515 | I38: 432 | J38: 351.96 | K38: =J38/49758.23 -> 0.0070734027 | L38: No NetZero target | M38: No NetZero target | N38: NOTARGET | O38: No NZT | P38: {=INDEX(CAT_NZ_Nov22!$Q$16:$Q$54,MATCH($B38,CAT_NZ_Nov22!$C$16:$C$53,0))} -> None | Q38: n | R38: n | S38: n | T38: =IF(AND(O38="Y",AND(P38="credible",Q38="Y")),"higher",IF(Q38="Y","lower",IF(AND(Q38="N",OR(O38="Y",P38="credible")),"lower","much lower"))) -> much lower | U38: =IF(AND(O38="Y",AND(P38="credible",R38="Y")),"higher",IF(R38="Y","lower",IF(AND(R38="N",OR(O38="Y",P38="credible")),"lower","much lower"))) -> much lower | V38: =IF(AND(O38="Y",AND(P38="credible",S38="Y")),"higher",IF(S38="Y","lower",IF(AND(S38="N",OR(O38="Y",P38="credible")),"lower","much lower"))) -> much lower | W38: =IF(AND($P38="credible",Q38="Y"),"stronger","weak") -> weak | X38: =IF(AND($P38="credible",R38="Y"),"stronger","weak") -> weak | Y38: =IF(AND($P38="credible",S38="Y"),"stronger","weak") -> weak | Z38: See 'CAT_NZ_Nov22' sheet | AB38: https://newclimate.org/resources/publications/emissions-scenarios-for-major-economies-2022-update | AH38: N | AI38: =IF(I38<0.9*J38,"Y","N") -> N
A39: Ethiopia | B39: ETH | C39: MtCO2e/yr | D39: 2019 | E39: 179 | F39: 306.20927 | G39: 2030 | H39: 347 | I39: 214 | J39: 183.37 | K39: =J39/49758.23 -> 0.0036852195 | L39: No NetZero target | M39: No NetZero target | N39: GHG | O39: N | P39: {=INDEX(CAT_NZ_Nov22!$Q$16:$Q$54,MATCH($B39,CAT_NZ_Nov22!$C$16:$C$53,0))} -> None | Q39: n | R39: n | S39: n | T39: =IF(AND(O39="Y",AND(P39="credible",Q39="Y")),"higher",IF(Q39="Y","lower",IF(AND(Q39="N",OR(O39="Y",P39="credible")),"lower","much lower"))) -> much lower | U39: =IF(AND(O39="Y",AND(P39="credible",R39="Y")),"higher",IF(R39="Y","lower",IF(AND(R39="N",OR(O39="Y",P39="credible")),"lower","much lower"))) -> much lower | V39: =IF(AND(O39="Y",AND(P39="credible",S39="Y")),"higher",IF(S39="Y","lower",IF(AND(S39="N",OR(O39="Y",P39="credible")),"lower","much lower"))) -> much lower | W39: =IF(AND($P39="credible",Q39="Y"),"stronger","weak") -> weak | X39: =IF(AND($P39="credible",R39="Y"),"stronger","weak") -> weak | Y39: =IF(AND($P39="credible",S39="Y"),"stronger","weak") -> weak | Z39: See 'CAT_NZ_Nov22' sheet | AB39: https://newclimate.org/resources/publications/emissions-scenarios-for-major-economies-2022-update | AH39: N | AI39: =IF(I39<0.9*J39,"Y","N") -> N
A40: Iran | B40: IRN | C40: MtCO2e/yr | D40: 2019 | E40: 1038 | F40: 907.52661 | G40: 2030 | H40: 1959 | I40: 1189 | J40: 893.78 | K40: =J40/49758.23 -> 0.017962456 | L40: No NetZero target | M40: No NetZero target | N40: NOTARGET | O40: No NZT | P40: {=INDEX(CAT_NZ_Nov22!$Q$16:$Q$54,MATCH($B40,CAT_NZ_Nov22!$C$16:$C$53,0))} -> None | Q40: n | R40: n | S40: n | T40: =IF(AND(O40="Y",AND(P40="credible",Q40="Y")),"higher",IF(Q40="Y","lower",IF(AND(Q40="N",OR(O40="Y",P40="credible")),"lower","much lower"))) -> much lower | U40: =IF(AND(O40="Y",AND(P40="credible",R40="Y")),"higher",IF(R40="Y","lower",IF(AND(R40="N",OR(O40="Y",P40="credible")),"lower","much lower"))) -> much lower | V40: =IF(AND(O40="Y",AND(P40="credible",S40="Y")),"higher",IF(S40="Y","lower",IF(AND(S40="N",OR(O40="Y",P40="credible")),"lower","much lower"))) -> much lower | W40: =IF(AND($P40="credible",Q40="Y"),"stronger","weak") -> weak | X40: =IF(AND($P40="credible",R40="Y"),"stronger","weak") -> weak | Y40: =IF(AND($P40="credible",S40="Y"),"stronger","weak") -> weak | Z40: See 'CAT_NZ_Nov22' sheet | AB40: https://newclimate.org/resources/publications/emissions-scenarios-for-major-economies-2022-update | AH40: N | AI40: =IF(I40<0.9*J40,"Y","N") -> N
...

Sheet CAT_NZ_Nov22
B7: Climate Action Tracker: | D7: Overview of Climate Action Tracker’s net zero target evaluations for G20 member countries (excluding France and Italy as both not separately analysed by the CAT) and selected other countries per key elements as of November 2022
B9: Date Published: | D9: 44875
B10: Climate Action Tracker Data: | D10: Do not redistribute without prior permission of the Climate Action Tracker team. Any reproduction of this data in graphical or numerical format must include credit to the Climate Action Tracker project.
D11: For further details on methodology, please see the Climate Action Tracker website:
D12: climateactiontracker.org/global/cat-net-zero-target-evaluations
B15: Country | C15: ISO | D15: Overall Rating | E15: Target year | F15: Emissions coverage | G15: International aviation and shipping | H15: Reductions or removals outside of own border | I15: Legal status | J15: Separate reduction & removal targets | K15: Review process | L15: Carbon dioxide removal | M15: Comprehensive planning | N15: Clarity on fairness of target | Q15: Comprehensive planning: score | U15: Underlying [government or government-endorsed] analysis identifies pathway and key measures for reaching net zero, with sector-specific detail | V15: Credible
B16: Chile | C16: CHL | D16: Acceptable | E16: 2050 | F16: All sectors and gases | G16: Excluded, or not specified | H16: Reaching net zero on own territory | I16: In law | J16: Yes | K16: Yes | L16: Transparent assumptions for domestic LULUCF and separately for domestic removals and storage | M16: Underlying [government or government-endorsed] analysis identifies pathway and key measures for reaching net zero, with sector-specific detail | N16: No reference to fairness / equity | Q16: =INDEX($V$15:$V$18,MATCH($M16,$U$15:$U$18, 0)) -> Credible | U16: Some information on anticipated pathway or measures for achieving net zero is available, but with limited detail | V16: Credible
B17: Colombia | C17: COL | D17: Acceptable | E17: 2050 | F17: All sectors and gases | G17: Excluded, or not specified | H17: Reaching net zero on own territory | I17: In law | J17: Yes | K17: Yes | L17: Transparent assumptions for domestic LULUCF or separately for domestic removals and storage | M17: Underlying [government or government-endorsed] analysis identifies pathway and key measures for reaching net zero, with sector-specific detail | N17: The government clearly explains why its net zero target is a fair contribution to the global goal of limiting warming to 1.5˚C above pre-industrial levels. For developed countries, this statement needs to include an explanation of how the government addresses the gap between its net zero target and what would be a fair target. | Q17: =INDEX($V$15:$V$18,MATCH($M17,$U$15:$U$18, 0)) -> Credible | U17: No pathway, measures or underlying analysis provided | V17: Weaker
B18: Costa Rica | C18: CRI | D18: Acceptable | E18: 2050 | F18: All sectors and gases | G18: Excluded, or not specified | H18: Reaching net zero on own territory | I18: Proposed Legislation or In Policy Document | J18: Yes | K18: Yes, but non-legally binding or in the process of establishing a review cycle | L18: Transparent assumptions for domestic LULUCF and separately for domestic removals and storage | M18: Underlying [government or government-endorsed] analysis identifies pathway and key measures for reaching net zero, with sector-specific detail | N18: No reference to fairness / equity | Q18: =INDEX($V$15:$V$18,MATCH($M18,$U$15:$U$18, 0)) -> Credible | U18: No information provided [only for targets announced or under discussion] | V18: None
B19: European Union | C19: EU27 | D19: Acceptable | E19: 2050 | F19: All sectors and gases | G19: Partially included | H19: Reaching net zero on own territory | I19: In law | J19: No or not specified | K19: Yes | L19: Transparent assumptions for domestic LULUCF and separately for domestic removals and storage | M19: Underlying [government or government-endorsed] analysis identifies pathway and key measures for reaching net zero, with sector-specific detail | N19: No reference to fairness / equity | Q19: =INDEX($V$15:$V$18,MATCH($M19,$U$15:$U$18, 0)) -> Credible
B20: United Kingdom | C20: GBR | D20: Acceptable | E20: 2050 | F20: All sectors and gases | G20: Included | H20: Reliance on offsetting - or leaving the option open to offset - own emissions with international offset credits (emission reductions or removals) not fulfilling the criteria above | I20: In law | J20: No or not specified | K20: Yes | L20: Transparent assumptions for domestic LULUCF and separately for domestic removals and storage | M20: Some information on anticipated pathway or measures for achieving net zero is available, but with limited detail | N20: Statement explaining why fair share in advisory (but not government) document | Q20: =INDEX($V$15:$V$18,MATCH($M20,$U$15:$U$18, 0)) -> Credible
B21: Viet Nam | C21: VNM | D21: Acceptable | E21: 2050 | F21: All sectors and gases | G21: Excluded, or not specified | H21: Reliance on offsetting - or leaving the option open to offset - own emissions with international offset credits (emission reductions or removals) not fulfilling the criteria above | I21: In law | J21: Yes | K21: Yes | L21: Transparent assumptions for domestic LULUCF or separately for domestic removals and storage | M21: Underlying [government or government-endorsed] analysis identifies pathway and key measures for reaching net zero, with sector-specific detail | N21: No reference to fairness / equity | Q21: =INDEX($V$15:$V$18,MATCH($M21,$U$15:$U$18, 0)) -> Credible
B22: Canada | C22: CAN | D22: Average | E22: 2050 | F22: All sectors and gases | G22: Excluded, or not specified | H22: Reaching net zero on own territory | I22: In law | J22: No or not specified | K22: Yes | L22: Non-transparent assumptions for domestic LULUCF and domestic removals and storage | M22: Some information on anticipated pathway or measures for achieving net zero is available, but with limited detail | N22: No reference to fairness / equity | Q22: =INDEX($V$15:$V$18,MATCH($M22,$U$15:$U$18, 0)) -> Credible
B23: Germany | C23: DEU | D23: Average | E23: 2045 | F23: All sectors and gases | G23: Excluded, or not specified | H23: Reliance on offsetting - or leaving the option open to offset - own emissions with international offset credits (emission reductions or removals) not fulfilling the criteria above | I23: In law | J23: Yes | K23: Yes | L23: Non-transparent assumptions for domestic LULUCF and domestic removals and storage | M23: Some information on anticipated pathway or measures for achieving net zero is available, but with limited detail | N23: Statement explaining why fair share in advisory (but not government) document | Q23: =INDEX($V$15:$V$18,MATCH($M23,$U$15:$U$18, 0)) -> Credible
B24: Nigeria | C24: NGA | D24: Average | E24: 2050–2070 | F24: Partial coverage (>95% of emissions excl. bunkers) | G24: Excluded, or not specified | H24: Reaching net zero on own territory | I24: Proposed Legislation or In Policy Document | J24: No or not specified | K24: Yes | L24: Non-transparent assumptions for domestic LULUCF and domestic removals and storage | M24: Some information on anticipated pathway or measures for achieving net zero is available, but with limited detail | N24: No reference to fairness / equity | Q24: =INDEX($V$15:$V$18,MATCH($M24,$U$15:$U$18, 0)) -> Credible
B25: South Korea | C25: KOR | D25: Average | E25: 2050 | F25: Incomplete coverage (<95% of emissions excl. bunkers), or not specified | G25: Excluded, or not specified | H25: Reaching net zero on own territory | I25: In law | J25: Yes | K25: Yes, but non-legally binding or in the process of establishing a review cycle | L25: Transparent assumptions for domestic LULUCF and separately for domestic removals and storage | M25: Some information on anticipated pathway or measures for achieving net zero is available, but with limited detail | N25: No reference to fairness / equity | Q25: =INDEX($V$15:$V$18,MATCH($M25,$U$15:$U$18, 0)) -> Credible
B26: Switzerland | C26: CHE | D26: Average | E26: 2050 | F26: All sectors and gases | G26: Included | H26: Limited reliance on removals outside of own territory (in the order of x% of current national emissions) from technological removal projects with a high certainty of permanence for more than 200 years and which do not negatively impact biodiversity (e.g. direct air capture with mineralisation). | I26: Proposed Legislation or In Policy Document | J26: Yes | K26: No | L26: Non-transparent assumptions for domestic LULUCF and domestic removals and storage | M26: Some information on anticipated pathway or measures for achieving net zero is available, but with limited detail | N26: No reference to fairness / equity | Q26: =INDEX($V$15:$V$18,MATCH($M26,$U$15:$U$18, 0)) -> Credible
B27: Thailand | C27: THA | D27: Average | E27: 2065 | F27: Partial coverage (>95% of emissions excl. bunkers) | G27: Excluded, or not specified | H27: Reaching net zero on own territory | I27: Proposed Legislation or In Policy Document | J27: Yes | K27: Yes, but non-legally binding or in the process of establishing a review cycle | L27: Transparent assumptions for domestic LULUCF and separately for domestic removals and storage | M27: Underlying [government or government-endorsed] analysis identifies pathway and key measures for reaching net zero, with sector-specific detail | N27: No reference to fairness / equity | Q27: =INDEX($V$15:$V$18,MATCH($M27,$U$15:$U$18, 0)) -> Credible
B28: United States | C28: USA | D28: Average | E28: 2050 | F28: All sectors and gases | G28: Excluded, or not specified | H28: Reliance on offsetting - or leaving the option open to offset - own emissions with international offset credits (emission reductions or removals) not fulfilling the criteria above | I28: Proposed Legislation or In Policy Document | J28: No or not specified | K28: Yes, but non-legally binding or in the process of establishing a review cycle | L28: Transparent assumptions for domestic LULUCF and separately for domestic removals and storage | M28: Some information on anticipated pathway or measures for achieving net zero is available, but with limited detail | N28: No reference to fairness / equity | Q28: =INDEX($V$15:$V$18,MATCH($M28,$U$15:$U$18, 0)) -> Credible
B29: Argentina | C29: ARG | D29: Poor | E29: 2050 | F29: All sectors and gases | G29: Excluded, or not specified | H29: Reliance on offsetting - or leaving the option open to offset - own emissions with international offset credits (emission reductions or removals) not fulfilling the criteria above | I29: Proposed Legislation or In Policy Document | J29: No or not specified | K29: No | L29: Non-transparent assumptions for domestic LULUCF and domestic removals and storage | M29: No pathway, measures or underlying analysis provided | N29: The government clearly explains why its net zero target is a fair contribution to the global goal of limiting warming to 1.5˚C above pre-industrial levels. For developed countries, this statement needs to include an explanation of how the government addresses the gap between its net zero target and what would be a fair target. | Q29: =INDEX($V$15:$V$18,MATCH($M29,$U$15:$U$18, 0)) -> Weaker
B30: Australia | C30: AUS | D30: Poor | E30: 2050 | F30: All sectors and gases | G30: Excluded, or not specified | H30: Reliance on offsetting - or leaving the option open to offset - own emissions with international offset credits (emission reductions or removals) not fulfilling the criteria above | I30: Proposed Legislation or In Policy Document | J30: No or not specified | K30: Yes, but non-legally binding or in the process of establishing a review cycle | L30: Non-transparent assumptions for domestic LULUCF and domestic removals and storage | M30: No pathway, measures or underlying analysis provided | N30: No reference to fairness / equity | Q30: =INDEX($V$15:$V$18,MATCH($M30,$U$15:$U$18, 0)) -> Weaker
B31: China | C31: CHN | D31: Poor | E31: 2060 | F31: Incomplete coverage (<95% of emissions excl. bunkers), or not specified | G31: Excluded, or not specified | H31: Reliance on offsetting - or leaving the option open to offset - own emissions with international offset credits (emission reductions or removals) not fulfilling the criteria above | I31: Proposed Legislation or In Policy Document | J31: No or not specified | K31: Yes, but non-legally binding or in the process of establishing a review cycle | L31: Non-transparent assumptions for domestic LULUCF and domestic removals and storage | M31: Some information on anticipated pathway or measures for achieving net zero is available, but with limited detail | N31: Statement explaining why fair share in advisory (but not government) document | Q31: =INDEX($V$15:$V$18,MATCH($M31,$U$15:$U$18, 0)) -> Credible
B32: Japan | C32: JPN | D32: Poor | E32: 2050 | F32: All sectors and gases | G32: Excluded, or not specified | H32: Reliance on offsetting - or leaving the option open to offset - own emissions with international offset credits (emission reductions or removals) not fulfilling the criteria above | I32: In law | J32: No or not specified | K32: Yes, but non-legally binding or in the process of establishing a review cycle | L32: Non-transparent assumptions for domestic LULUCF and domestic removals and storage | M32: Some information on anticipated pathway or measures for achieving net zero is available, but with limited detail | N32: No reference to fairness / equity | Q32: =INDEX($V$15:$V$18,MATCH($M32,$U$15:$U$18, 0)) -> Credible
B33: Kazakhstan | C33: KAZ | D33: Poor | E33: 2060 | F33: All sectors and gases | G33: Excluded, or not specified | H33: Reliance on offsetting - or leaving the option open to offset - own emissions with international offset credits (emission reductions or removals) not fulfilling the criteria above | I33: Proposed Legislation or In Policy Document | J33: No or not specified | K33: No | L33: Transparent assumptions for domestic LULUCF or separately for domestic removals and storage | M33: Underlying [government or government-endorsed] analysis identifies pathway and key measures for reaching net zero, with sector-specific detail | N33: No reference to fairness / equity | Q33: =INDEX($V$15:$V$18,MATCH($M33,$U$15:$U$18, 0)) -> Credible
B34: New Zealand | C34: NZL | D34: Poor | E34: 2050 | F34: Incomplete coverage (<95% of emissions excl. bunkers), or not specified | G34: Excluded, or not specified | H34: Reliance on offsetting - or leaving the option open to offset - own emissions with international offset credits (emission reductions or removals) not fulfilling the criteria above | I34: In law | J34: No or not specified | K34: Yes | L34: Non-transparent assumptions for domestic LULUCF and domestic removals and storage | M34: Some information on anticipated pathway or measures for achieving net zero is available, but with limited detail | N34: No reference to fairness / equity | Q34: =INDEX($V$15:$V$18,MATCH($M34,$U$15:$U$18, 0)) -> Credible
B35: Russian Federation | C35: RUS | D35: Poor | E35: 2060 | F35: All sectors and gases | G35: Excluded, or not specified | H35: Reliance on offsetting - or leaving the option open to offset - own emissions with international offset credits (emission reductions or removals) not fulfilling the criteria above | I35: In law | J35: No or not specified | K35: Yes, but non-legally binding or in the process of establishing a review cycle | L35: Non-transparent assumptions for domestic LULUCF and domestic removals and storage | M35: Some information on anticipated pathway or measures for achieving net zero is available, but with limited detail | N35: No reference to fairness / equity | Q35: =INDEX($V$15:$V$18,MATCH($M35,$U$15:$U$18, 0)) -> Credible
B36: Singapore | C36: SGP | D36: Poor | E36: 2050 | F36: All sectors and gases | G36: Excluded, or not specified | H36: Reliance on offsetting - or leaving the option open to offset - own emissions with international offset credits (emission reductions or removals) not fulfilling the criteria above | I36: Proposed Legislation or In Policy Document | J36: No or not specified | K36: Yes, but non-legally binding or in the process of establishing a review cycle | L36: Non-transparent assumptions for domestic LULUCF and domestic removals and storage | M36: Some information on anticipated pathway or measures for achieving net zero is available, but with limited detail | N36: No reference to fairness / equity | Q36: =INDEX($V$15:$V$18,MATCH($M36,$U$15:$U$18, 0)) -> Credible
... B39: Brazil | C39: BRA | D39: Information incomplete | E39: 2050 | F39: No information provided [only for targets announced or under discussion] | G39: No information provided [only for targets announced or under discussion] | H39: No information provided [only for targets announced or under discussion] | I39: Proposed Legislation or In Policy Document | J39: No information provided [only for targets announced or under discussion] | K39: No information provided [only for targets announced or under discussion] | L39: No information provided [only for targets announced or under discussion] | M39: No information provided [only for targets announced or under discussion] | N39: No information provided [only for targets announced or under discussion] | Q39: =INDEX($V$15:$V$18,MATCH($M39,$U$15:$U$18, 0)) -> None
B40: Ethiopia | C40: ETH | D40: Information incomplete | E40: Not defined | F40: No information provided [only for targets announced or under discussion] | G40: No information provided [only for targets announced or under discussion] | H40: No information provided [only for targets announced or under discussion] | I40: Proposed Legislation or In Policy Document | J40: No information provided [only for targets announced or under discussion] | K40: No information provided [only for targets announced or under discussion] | L40: No information provided [only for targets announced or under discussion] | M40: No information provided [only for targets announced or under discussion] | N40: No information provided [only for targets announced or under discussion] | Q40: =INDEX($V$15:$V$18,MATCH($M40,$U$15:$U$18, 0)) -> None
B41: India | C41: IND | D41: Information incomplete | E41: 2070 | F41: No information provided [only for targets announced or under discussion] | G41: No information provided [only for targets announced or under discussion] | H41: No information provided [only for targets announced or under discussion] | I41: Target announced by Head of Government or equivalent | J41: No information provided [only for targets announced or under discussion] | K41: No information provided [only for targets announced or under discussion] | L41: No information provided [only for targets announced or under discussion] | M41: No information provided [only for targets announced or under discussion] | N41: No information provided [only for targets announced or under discussion] | Q41: =INDEX($V$15:$V$18,MATCH($M41,$U$15:$U$18, 0)) -> None
B42: Indonesia | C42: IDN | D42: Information incomplete | E42: 2060 | F42: No information provided [only for targets announced or under discussion] | G42: No information provided [only for targets announced or under discussion] | H42: No information provided [only for targets announced or under discussion] | I42: Proposed Legislation or In Policy Document | J42: No information provided [only for targets announced or under discussion] | K42: No information provided [only for targets announced or under discussion] | L42: No information provided [only for targets announced or under discussion] | M42: No information provided [only for targets announced or under discussion] | N42: No information provided [only for targets announced or under discussion] | Q42: =INDEX($V$15:$V$18,MATCH($M42,$U$15:$U$18, 0)) -> None
B43: Peru | C43: PER | D43: Information incomplete | E43: 2050 | F43: No information provided [only for targets announced or under discussion] | G43: No information provided [only for targets announced or under discussion] | H43: No information provided [only for targets announced or under discussion] | I43: Proposed Legislation or In Policy Document | J43: No information provided [only for targets announced or under discussion] | K43: No information provided [only for targets announced or under discussion] | L43: No information provided [only for targets announced or under discussion] | M43: No information provided [only for targets announced or under discussion] | N43: No information provided [only for targets announced or under discussion] | Q43: =INDEX($V$15:$V$18,MATCH($M43,$U$15:$U$18, 0)) -> None
B44: Saudi Arabia | C44: SAU | D44: Information incomplete | E44: 2060 | F44: Incomplete coverage (<95% of emissions excl. bunkers), or not specified | G44: No information provided [only for targets announced or under discussion] | H44: No information provided [only for targets announced or under discussion] | I44: Target announced by Head of Government or equivalent | J44: No information provided [only for targets announced or under discussion] | K44: No information provided [only for targets announced or under discussion] | L44: No information provided [only for targets announced or under discussion] | M44: No pathway, measures or underlying analysis provided | N44: No information provided [only for targets announced or under discussion] | Q44: =INDEX($V$15:$V$18,MATCH($M44,$U$15:$U$18, 0)) -> Weaker
B45: South Africa | C45: ZAF | D45: Information incomplete | E45: 2050 | F45: No information provided [only for targets announced or under discussion] | G45: No information provided [only for targets announced or under discussion] | H45: No information provided [only for targets announced or under discussion] | I45: Proposed Legislation or In Policy Document | J45: No information provided [only for targets announced or under discussion] | K45: No information provided [only for targets announced or under discussion] | L45: No information provided [only for targets announced or under discussion] | M45: No information provided [only for targets announced or under discussion] | N45: No information provided [only for targets announced or under discussion] | Q45: =INDEX($V$15:$V$18,MATCH($M45,$U$15:$U$18, 0)) -> None
